Workbook

Sheet Resumen
B2: Estimación Funcional Cosmic — Leodega / Leodeguita
B4: Rol | C4: E | D4: X | E4: R | F4: W | G4: CFP | H4: % del total
B5: Gestor de bodega | C5: =Gestor!M36 -> 12 | D5: =Gestor!N36 -> 24 | E5: =Gestor!O36 -> 17 | F5: =Gestor!P36 -> 10 | G5: =Gestor!Q36 -> 63 | H5: =G5/$G$10 -> 0.19444444
B6: Cliente | C6: =Cliente!N57 -> 34 | D6: =Cliente!O57 -> 42 | E6: =Cliente!P57 -> 28 | F6: =Cliente!Q57 -> 16 | G6: =Cliente!R57 -> 120 | H6: =G6/$G$10 -> 0.37037037
B7: Administrador de plataforma | C7: =Administrador!J24 -> 10 | D7: =Administrador!K24 -> 12 | E7: =Administrador!L24 -> 9 | F7: =Administrador!M24 -> 6 | G7: =Administrador!N24 -> 37 | H7: =G7/$G$10 -> 0.11419753
B8: Organización / Empresa | C8: =Organización!J30 -> 16 | D8: =Organización!K30 -> 18 | E8: =Organización!L30 -> 15 | F8: =Organización!M30 -> 7 | G8: =Organización!N30 -> 56 | H8: =G8/$G$10 -> 0.17283951
B9: Leodeguita (app móvil) | C9: =Leodeguita!J30 -> 14 | D9: =Leodeguita!K30 -> 18 | E9: =Leodeguita!L30 -> 15 | F9: =Leodeguita!M30 -> 1 | G9: =Leodeguita!N30 -> 48 | H9: =G9/$G$10 -> 0.14814815
B10: Total Sistema | C10: =SUM(C5:C9) -> 86 | D10: =SUM(D5:D9) -> 114 | E10: =SUM(E5:E9) -> 84 | F10: =SUM(F5:F9) -> 40 | G10: =SUM(G5:G9) -> 324 | H10: 100%
B12: Notación:
B14: • E = Entrada · X = Salida · R = Lectura · W = Escritura. 1 movimiento de datos = 1 CFP (COSMIC Function Point).
B15: • Unidad de análisis: un proceso funcional por escenario (S1, S2, S3) de cada Historia de Usuario.
B16: • Los totales por componente y por rol son fórmulas que se recalculan si se modifica cualquier movimiento.
B17: • Alcance: prototipo con pagos y endpoint de inventario simulados (los movimientos igual se contabilizan).

Sheet Gestor
B2: Gestor De Bodega (Storage Manager — HUG)
B4: Componentes | D4: Historia | E4: Procesos Funcionales | F4: Grupos de datos | M4: Metodología COSMIC
F6: G1 Bodega | G6: G2 Reserva | H6: G3 Consulta / mensaje | I6: G4 Contrato | J6: G5 Notificación | K6: G6 Chat | L6: G7 Permiso de bomberos | M6: E | N6: X | O6: R | P6: W | Q6: CFP
B8: Comunicación con clientes | D8: HUG-01 (S1) | E8: Recibir notificación de consulta previa | H8: X | J8: X | M8: 0 | N8: 1 | O8: 1 | P8: 0 | Q8: =SUM(M8:P8) -> 2
D9: HUG-01 (S2) | E9: Responder consulta previa | H9: X | M9: 1 | N9: 1 | O9: 0 | P9: 1 | Q9: =SUM(M9:P9) -> 3
D10: HUG-01 (S3) | E10: Visualizar consultas pendientes | H10: X | M10: 0 | N10: 1 | O10: 1 | P10: 0 | Q10: =SUM(M10:P10) -> 2
D11: HUG-03 (S1) | E11: Enviar mensaje en chat de contrato activo | J11: X | K11: X | M11: 1 | N11: 1 | O11: 0 | P11: 1 | Q11: =SUM(M11:P11) -> 3
D12: HUG-03 (S2) | E12: Recibir mensaje de cliente en chat activo | J12: X | K12: X | M12: 0 | N12: 1 | O12: 1 | P12: 0 | Q12: =SUM(M12:P12) -> 2
D13: HUG-03 (S3) | E13: Validar chat de contrato finalizado | I13: X | M13: 0 | N13: 1 | O13: 1 | P13: 0 | Q13: =SUM(M13:P13) -> 2
B14: Total — Comunicación con clientes | M14: =SUM(M8:M13) -> 2 | N14: =SUM(N8:N13) -> 6 | O14: =SUM(O8:O13) -> 4 | P14: =SUM(P8:P13) -> 2 | Q14: =SUM(Q8:Q13) -> 14
B15: Notificaciones de pago y contratos | D15: HUG-02 (S1) | E15: Notificación de pago confirmado | I15: X | J15: X | M15: 0 | N15: 1 | O15: 1 | P15: 1 | Q15: =SUM(M15:P15) -> 3
D16: HUG-02 (S2) | E16: Liberación por no pago | G16: X | J16: X | M16: 0 | N16: 1 | O16: 1 | P16: 1 | Q16: =SUM(M16:P16) -> 3
D17: HUG-02 (S3) | E17: Ver contratos activos | I17: X | M17: 0 | N17: 1 | O17: 1 | P17: 0 | Q17: =SUM(M17:P17) -> 2
B18: Total — Notificaciones de pago y contratos | M18: =SUM(M15:M17) -> 0 | N18: =SUM(N15:N17) -> 3 | O18: =SUM(O15:O17) -> 3 | P18: =SUM(P15:P17) -> 2 | Q18: =SUM(Q15:Q17) -> 8
B19: Gestión de bodegas | D19: HUG-04 (S1) | E19: Registrar bodega con permiso | F19: X | L19: X | M19: 1 | N19: 1 | O19: 0 | P19: 1 | Q19: =SUM(M19:P19) -> 3
D20: HUG-04 (S2) | E20: Registro sin permiso | F20: X | L20: X | M20: 1 | N20: 1 | O20: 0 | P20: 0 | Q20: =SUM(M20:P20) -> 2
D21: HUG-04 (S3) | E21: Registro con campos faltantes | F21: X | M21: 1 | N21: 1 | O21: 0 | P21: 0 | Q21: =SUM(M21:P21) -> 2
D22: HUG-07 (S1) | E22: Eliminar bodega sin reservas | F22: X | G22: X | M22: 0 | N22: 1 | O22: 1 | P22: 1 | Q22: =SUM(M22:P22) -> 3
D23: HUG-07 (S2) | E23: Intento de eliminar con reservas activas | G23: X | M23: 0 | N23: 1 | O23: 1 | P23: 0 | Q23: =SUM(M23:P23) -> 2
D24: HUG-07 (S3) | E24: Eliminar bodega con historial | F24: X | G24: X | M24: 0 | N24: 1 | O24: 1 | P24: 1 | Q24: =SUM(M24:P24) -> 3
D25: HUG-08 (S1) | E25: Editar bodega | F25: X | M25: 1 | N25: 1 | O25: 1 | P25: 1 | Q25: =SUM(M25:P25) -> 4
D26: HUG-08 (S2) | E26: Edición con datos inválidos | F26: X | M26: 1 | N26: 1 | O26: 0 | P26: 0 | Q26: =SUM(M26:P26) -> 2
D27: HUG-08 (S3) | E27: Edición con reservas activas | F27: X | G27: X | M27: 1 | N27: 1 | O27: 1 | P27: 1 | Q27: =SUM(M27:P27) -> 4
B28: Total — Gestión de bodegas | M28: =SUM(M19:M27) -> 6 | N28: =SUM(N19:N27) -> 9 | O28: =SUM(O19:O27) -> 5 | P28: =SUM(P19:P27) -> 5 | Q28: =SUM(Q19:Q27) -> 25
B29: Gestión de reservas | D29: HUG-05 (S1) | E29: Ver lista de reservas | G29: X | M29: 0 | N29: 1 | O29: 1 | P29: 0 | Q29: =SUM(M29:P29) -> 2
D30: HUG-05 (S2) | E30: Filtrar reservas | G30: X | M30: 1 | N30: 1 | O30: 1 | P30: 0 | Q30: =SUM(M30:P30) -> 3
D31: HUG-05 (S3) | E31: Ver detalle de reserva | G31: X | M31: 1 | N31: 1 | O31: 1 | P31: 0 | Q31: =SUM(M31:P31) -> 3
D32: HUG-06 (S1) | E32: Cancelar reserva futura pagada | G32: X | M32: 1 | N32: 1 | O32: 1 | P32: 1 | Q32: =SUM(M32:P32) -> 4
D33: HUG-06 (S2) | E33: Cancelar reserva iniciada | G33: X | M33: 0 | N33: 1 | O33: 1 | P33: 0 | Q33: =SUM(M33:P33) -> 2
D34: HUG-06 (S3) | E34: Cancelar sin razón | G34: X | M34: 1 | N34: 1 | O34: 0 | P34: 0 | Q34: =SUM(M34:P34) -> 2
B35: Total — Gestión de reservas | M35: =SUM(M29:M34) -> 4 | N35: =SUM(N29:N34) -> 6 | O35: =SUM(O29:O34) -> 5 | P35: =SUM(P29:P34) -> 1 | Q35: =SUM(Q29:Q34) -> 16
B36: Total Gestor De Bodega | M36: =M14+M18+M28+M35 -> 12 | N36: =N14+N18+N28+N35 -> 24 | O36: =O14+O18+O28+O35 -> 17 | P36: =P14+P18+P28+P35 -> 10 | Q36: =Q14+Q18+Q28+Q35 -> 63
B38: Leyenda — Grupos de datos
B39: G1 — Bodega | E39: Datos del espacio: dimensiones, ubicación, fotos, tarifa mensual, estado (disponible/ocupada/inactiva).
B40: G2 — Reserva | E40: Reservas hechas sobre las bodegas del manager: fechas, cliente, estado de pago, importe, motivo de cancelación.
B41: G3 — Consulta / mensaje | E41: Consultas previas a la reserva: contenido del mensaje, cliente, estado (respondida/pendiente).
B42: G4 — Contrato | E42: Contrato activo entre manager y cliente: cliente, espacio, fechas, importe, estado.
B43: G5 — Notificación | E43: Alertas enviadas al manager: pago confirmado, nuevo mensaje, liberación de espacio.
B44: G6 — Chat | E44: Hilo de conversación durante un contrato activo: mensajes, timestamps, emisor.
B45: G7 — Permiso de bomberos | E45: Documento del permiso vigente de bomberos adjunto a la bodega.
...

Sheet Cliente
B2: Cliente (Client — HUC)
B4: Componentes | D4: Historia | E4: Procesos Funcionales | F4: Grupos de datos | N4: Metodología COSMIC
F6: G1 Bodega / espacio | G6: G2 Reserva / disponibilidad | H6: G3 Pago / comprobante | I6: G4 Mensaje / hilo | J6: G5 Reporte | K6: G6 Reseña / calificación | L6: G7 Inventario | M6: G8 Invitación / membresía | N6: E | O6: X | P6: R | Q6: W | R6: CFP
B8: Búsqueda y exploración de bodegas | D8: HUC-01 (S1) | E8: Buscar bodegas con filtros | F8: X | N8: 1 | O8: 1 | P8: 1 | Q8: 0 | R8: =SUM(N8:Q8) -> 3
D9: HUC-01 (S2) | E9: Búsqueda sin resultados | F9: X | N9: 1 | O9: 1 | P9: 1 | Q9: 0 | R9: =SUM(N9:Q9) -> 3
D10: HUC-01 (S3) | E10: Vista de mapa | F10: X | N10: 1 | O10: 1 | P10: 1 | Q10: 0 | R10: =SUM(N10:Q10) -> 3
D11: HUC-02 (S1) | E11: Ver detalle de bodega | F11: X | N11: 1 | O11: 1 | P11: 1 | Q11: 0 | R11: =SUM(N11:Q11) -> 3
D12: HUC-02 (S2) | E12: Bodega no disponible | F12: X | N12: 1 | O12: 1 | P12: 1 | Q12: 0 | R12: =SUM(N12:Q12) -> 3
D13: HUC-02 (S3) | E13: Bodega inexistente | F13: X | N13: 1 | O13: 1 | P13: 1 | Q13: 0 | R13: =SUM(N13:Q13) -> 3
B14: Total — Búsqueda y exploración de bodegas | N14: =SUM(N8:N13) -> 6 | O14: =SUM(O8:O13) -> 6 | P14: =SUM(P8:P13) -> 6 | Q14: =SUM(Q8:Q13) -> 0 | R14: =SUM(R8:R13) -> 18
B15: Reserva y pago | D15: HUC-03 (S1) | E15: Crear reserva | F15: X | G15: X | N15: 1 | O15: 1 | P15: 1 | Q15: 1 | R15: =SUM(N15:Q15) -> 4
D16: HUC-03 (S2) | E16: Reserva con conflictos de fechas | G16: X | N16: 1 | O16: 1 | P16: 1 | Q16: 0 | R16: =SUM(N16:Q16) -> 3
D17: HUC-03 (S3) | E17: Reserva sin sesión | G17: X | N17: 1 | O17: 1 | P17: 0 | Q17: 0 | R17: =SUM(N17:Q17) -> 2
D18: HUC-05 (S1) | E18: Pago simulado | G18: X | H18: X | N18: 1 | O18: 1 | P18: 1 | Q18: 1 | R18: =SUM(N18:Q18) -> 4
D19: HUC-05 (S2) | E19: Pago después de deadline | G19: X | N19: 1 | O19: 1 | P19: 1 | Q19: 1 | R19: =SUM(N19:Q19) -> 4
D20: HUC-05 (S3) | E20: Ver recibo de pago | H20: X | N20: 1 | O20: 1 | P20: 1 | Q20: 0 | R20: =SUM(N20:Q20) -> 3
B21: Total — Reserva y pago | N21: =SUM(N15:N20) -> 6 | O21: =SUM(O15:O20) -> 6 | P21: =SUM(P15:P20) -> 5 | Q21: =SUM(Q15:Q20) -> 3 | R21: =SUM(R15:R20) -> 20
B22: Comunicación con el manager | D22: HUC-04 (S1) | E22: Enviar consulta previa | I22: X | N22: 1 | O22: 1 | P22: 0 | Q22: 1 | R22: =SUM(N22:Q22) -> 3
D23: HUC-04 (S2) | E23: Recibir respuesta del manager | I23: X | N23: 0 | O23: 1 | P23: 1 | Q23: 0 | R23: =SUM(N23:Q23) -> 2
D24: HUC-04 (S3) | E24: Consulta sin sesión | I24: X | N24: 1 | O24: 1 | P24: 0 | Q24: 0 | R24: =SUM(N24:Q24) -> 2
D25: HUC-06 (S1) | E25: Enviar mensaje en chat activo | I25: X | N25: 1 | O25: 1 | P25: 0 | Q25: 1 | R25: =SUM(N25:Q25) -> 3
D26: HUC-06 (S2) | E26: Chat en reserva no activa | G26: X | I26: X | N26: 1 | O26: 1 | P26: 1 | Q26: 0 | R26: =SUM(N26:Q26) -> 3
D27: HUC-06 (S3) | E27: Recibir mensaje del manager | I27: X | N27: 0 | O27: 1 | P27: 1 | Q27: 0 | R27: =SUM(N27:Q27) -> 2
B28: Total — Comunicación con el manager | N28: =SUM(N22:N27) -> 4 | O28: =SUM(O22:O27) -> 6 | P28: =SUM(P22:P27) -> 3 | Q28: =SUM(Q22:Q27) -> 2 | R28: =SUM(R22:R27) -> 15
B29: Gestión de reservas e historial | D29: HUC-07 (S1) | E29: Ver historial de reservas | G29: X | N29: 0 | O29: 1 | P29: 1 | Q29: 0 | R29: =SUM(N29:Q29) -> 2
D30: HUC-07 (S2) | E30: Cancelar reserva activa | G30: X | N30: 1 | O30: 1 | P30: 1 | Q30: 1 | R30: =SUM(N30:Q30) -> 4
D31: HUC-07 (S3) | E31: Cancelar reserva iniciada | G31: X | N31: 0 | O31: 1 | P31: 1 | Q31: 0 | R31: =SUM(N31:Q31) -> 2
B32: Total — Gestión de reservas e historial | N32: =SUM(N29:N31) -> 1 | O32: =SUM(O29:O31) -> 3 | P32: =SUM(P29:P31) -> 3 | Q32: =SUM(Q29:Q31) -> 1 | R32: =SUM(R29:R31) -> 8
B33: Reportes y reseñas | D33: HUC-08 (S1) | E33: Crear reporte | J33: X | N33: 1 | O33: 1 | P33: 0 | Q33: 1 | R33: =SUM(N33:Q33) -> 3
D34: HUC-08 (S2) | E34: Seguimiento de reporte | J34: X | N34: 0 | O34: 1 | P34: 1 | Q34: 0 | R34: =SUM(N34:Q34) -> 2
D35: HUC-08 (S3) | E35: Reporte sin descripción | J35: X | N35: 1 | O35: 1 | P35: 0 | Q35: 0 | R35: =SUM(N35:Q35) -> 2
D36: HUC-09 (S1) | E36: Enviar reseña | K36: X | N36: 1 | O36: 1 | P36: 0 | Q36: 1 | R36: =SUM(N36:Q36) -> 3
D37: HUC-09 (S2) | E37: Reseña en reserva sin finalizar | G37: X | K37: X | N37: 0 | O37: 1 | P37: 1 | Q37: 0 | R37: =SUM(N37:Q37) -> 2
D38: HUC-09 (S3) | E38: Segunda reseña | K38: X | N38: 0 | O38: 1 | P38: 1 | Q38: 0 | R38: =SUM(N38:Q38) -> 2
B39: Total — Reportes y reseñas | N39: =SUM(N33:N38) -> 3 | O39: =SUM(O33:O38) -> 6 | P39: =SUM(P33:P38) -> 3 | Q39: =SUM(Q33:Q38) -> 2 | R39: =SUM(R33:R38) -> 14
B40: Integración de inventario | D40: HUC-10 (S1) | E40: Registrar endpoint externo | L40: X | N40: 1 | O40: 1 | P40: 1 | Q40: 1 | R40: =SUM(N40:Q40) -> 4
D41: HUC-10 (S2) | E41: Endpoint inválido | L41: X | N41: 1 | O41: 1 | P41: 1 | Q41: 0 | R41: =SUM(N41:Q41) -> 3
D42: HUC-10 (S3) | E42: Actualizar conexión | L42: X | N42: 1 | O42: 1 | P42: 1 | Q42: 1 | R42: =SUM(N42:Q42) -> 4
D43: HUC-11 (S1) | E43: Configurar mapeo inicial | L43: X | N43: 0 | O43: 1 | P43: 1 | Q43: 0 | R43: =SUM(N43:Q43) -> 2
D44: HUC-11 (S2) | E44: Guardar mapeo | L44: X | N44: 1 | O44: 1 | P44: 0 | Q44: 1 | R44: =SUM(N44:Q44) -> 3
...

Sheet Administrador
B2: Administrador (Administrator — HUA)
B4: Componentes | D4: Historia | E4: Procesos Funcionales | F4: Grupos de datos | J4: Metodología COSMIC
F6: G1 Bodega / permiso | G6: G2 Métricas / dashboard | H6: G3 Usuario / cuenta | I6: G4 Reporte | J6: E | K6: X | L6: R | M6: W | N6: CFP
B8: Moderación de bodegas | D8: HUA-01 (S1) | E8: Aprobar bodega con permiso válido | F8: X | J8: 1 | K8: 1 | L8: 1 | M8: 1 | N8: =SUM(J8:M8) -> 4
D9: HUA-01 (S2) | E9: Rechazar por permiso inválido | F9: X | J9: 1 | K9: 1 | L9: 1 | M9: 1 | N9: =SUM(J9:M9) -> 4
D10: HUA-01 (S3) | E10: Envío sin documento | F10: X | J10: 1 | K10: 1 | L10: 0 | M10: 0 | N10: =SUM(J10:M10) -> 2
B11: Total — Moderación de bodegas | J11: =SUM(J8:J10) -> 3 | K11: =SUM(K8:K10) -> 3 | L11: =SUM(L8:L10) -> 2 | M11: =SUM(M8:M10) -> 2 | N11: =SUM(N8:N10) -> 10
B12: Monitoreo de plataforma | D12: HUA-02 (S1) | E12: Cargar dashboard | G12: X | J12: 0 | K12: 1 | L12: 1 | M12: 0 | N12: =SUM(J12:M12) -> 2
D13: HUA-02 (S2) | E13: Filtrar por período | G13: X | J13: 1 | K13: 1 | L13: 1 | M13: 0 | N13: =SUM(J13:M13) -> 3
D14: HUA-02 (S3) | E14: Indicador de reportes no resueltos | G14: X | I14: X | J14: 0 | K14: 1 | L14: 1 | M14: 0 | N14: =SUM(J14:M14) -> 2
B15: Total — Monitoreo de plataforma | J15: =SUM(J12:J14) -> 1 | K15: =SUM(K12:K14) -> 3 | L15: =SUM(L12:L14) -> 3 | M15: =SUM(M12:M14) -> 0 | N15: =SUM(N12:N14) -> 7
B16: Gestión de usuarios | D16: HUA-03 (S1) | E16: Bloquear cuenta | H16: X | J16: 1 | K16: 1 | L16: 1 | M16: 1 | N16: =SUM(J16:M16) -> 4
D17: HUA-03 (S2) | E17: Login de usuario bloqueado | H17: X | J17: 1 | K17: 1 | L17: 1 | M17: 0 | N17: =SUM(J17:M17) -> 3
D18: HUA-03 (S3) | E18: Reactivar cuenta | H18: X | J18: 1 | K18: 1 | L18: 1 | M18: 1 | N18: =SUM(J18:M18) -> 4
B19: Total — Gestión de usuarios | J19: =SUM(J16:J18) -> 3 | K19: =SUM(K16:K18) -> 3 | L19: =SUM(L16:L18) -> 3 | M19: =SUM(M16:M18) -> 2 | N19: =SUM(N16:N18) -> 11
B20: Gestión de reportes | D20: HUA-04 (S1) | E20: Revisar reporte pendiente | I20: X | J20: 1 | K20: 1 | L20: 1 | M20: 1 | N20: =SUM(J20:M20) -> 4
D21: HUA-04 (S2) | E21: Responder y resolver reporte | I21: X | J21: 1 | K21: 1 | L21: 0 | M21: 1 | N21: =SUM(J21:M21) -> 3
D22: HUA-04 (S3) | E22: Resolver sin respuesta | I22: X | J22: 1 | K22: 1 | L22: 0 | M22: 0 | N22: =SUM(J22:M22) -> 2
B23: Total — Gestión de reportes | J23: =SUM(J20:J22) -> 3 | K23: =SUM(K20:K22) -> 3 | L23: =SUM(L20:L22) -> 1 | M23: =SUM(M20:M22) -> 2 | N23: =SUM(N20:N22) -> 9
B24: Total Administrador | J24: =J11+J15+J19+J23 -> 10 | K24: =K11+K15+K19+K23 -> 12 | L24: =L11+L15+L19+L23 -> 9 | M24: =M11+M15+M19+M23 -> 6 | N24: =N11+N15+N19+N23 -> 37
B26: LEYENDA — Grupos de datos
B27: G1 — Bodega / permiso | E27: Bodega en revisión: datos del warehouse y documento de permiso de bomberos adjunto, estado de publicación.
B28: G2 — Métricas / dashboard | E28: Indicadores globales de la plataforma: bodegas por estado, usuarios por rol, monto transaccionado, reservas en curso, reportes pendientes, filtros de período.
B29: G3 — Usuario / cuenta | E29: Cuenta de usuario: perfil, rol, estado (activo/bloqueado), tokens de acceso, log de auditoría, motivo de bloqueo/reactivación.
B30: G4 — Reporte | E30: Reporte de incidente recibido: tipo, descripción, bodega y reserva vinculadas, estado, respuesta del administrador.
B32: Notación COSMIC: E = Entrada (el sistema recibe datos) · X = Salida (el sistema envía datos) · R = Lectura (el sistema lee datos almacenados) · W = Escritura (el sistema almacena/modifica datos) · 1 movimiento de datos = 1 CFP

Sheet Organización
B2: Organización / Compañía (Organisation — HUE)
B4: Componentes | D4: Historia | E4: Procesos Funcionales | F4: Grupos de datos | J4: Metodología COSMIC
F6: G1 Organización | G6: G2 Miembro / invitación | H6: G3 Contexto operativo | I6: G4 Reserva empresarial | J6: E | K6: X | L6: R | M6: W | N6: CFP
B8: Creación y administración de organización | D8: HUE-04 (S1) | E8: Crear organización | F8: X | J8: 1 | K8: 1 | L8: 1 | M8: 1 | N8: =SUM(J8:M8) -> 4
D9: HUE-04 (S2) | E9: RUC duplicado | F9: X | J9: 1 | K9: 1 | L9: 1 | M9: 0 | N9: =SUM(J9:M9) -> 3
D10: HUE-04 (S3) | E10: Crear con campos faltantes | F10: X | J10: 1 | K10: 1 | L10: 0 | M10: 0 | N10: =SUM(J10:M10) -> 2
D11: HUE-03 (S1) | E11: Cargar panel admin empresarial | F11: X | G11: X | J11: 0 | K11: 1 | L11: 1 | M11: 0 | N11: =SUM(J11:M11) -> 2
D12: HUE-03 (S2) | E12: Remover miembro | G12: X | J12: 1 | K12: 1 | L12: 1 | M12: 1 | N12: =SUM(J12:M12) -> 4
D13: HUE-03 (S3) | E13: Ver historial de acciones | F13: X | J13: 0 | K13: 1 | L13: 1 | M13: 0 | N13: =SUM(J13:M13) -> 2
B14: Total — Creación y administración de organización | J14: =SUM(J8:J13) -> 4 | K14: =SUM(K8:K13) -> 6 | L14: =SUM(L8:L13) -> 5 | M14: =SUM(M8:M13) -> 2 | N14: =SUM(N8:N13) -> 17
B15: Gestión de miembros | D15: HUE-01 (S1) | E15: Enviar invitación | G15: X | J15: 1 | K15: 1 | L15: 1 | M15: 1 | N15: =SUM(J15:M15) -> 4
D16: HUE-01 (S2) | E16: Invitar a manager | G16: X | J16: 1 | K16: 1 | L16: 1 | M16: 0 | N16: =SUM(J16:M16) -> 3
D17: HUE-01 (S3) | E17: Invitar miembro existente | G17: X | J17: 1 | K17: 1 | L17: 1 | M17: 0 | N17: =SUM(J17:M17) -> 3
B18: Total — Gestión de miembros | J18: =SUM(J15:J17) -> 3 | K18: =SUM(K15:K17) -> 3 | L18: =SUM(L15:L17) -> 3 | M18: =SUM(M15:M17) -> 1 | N18: =SUM(N15:N17) -> 10
B19: Contexto operativo | D19: HUE-02 (S1) | E19: Cambiar a contexto organización | F19: X | H19: X | J19: 1 | K19: 1 | L19: 1 | M19: 0 | N19: =SUM(J19:M19) -> 3
D20: HUE-02 (S2) | E20: Cambiar a contexto personal | H20: X | J20: 1 | K20: 1 | L20: 0 | M20: 0 | N20: =SUM(J20:M20) -> 2
D21: HUE-02 (S3) | E21: Login con una organización | H21: X | J21: 1 | K21: 1 | L21: 1 | M21: 0 | N21: =SUM(J21:M21) -> 3
B22: Total — Contexto operativo | J22: =SUM(J19:J21) -> 3 | K22: =SUM(K19:K21) -> 3 | L22: =SUM(L19:L21) -> 2 | M22: =SUM(M19:M21) -> 0 | N22: =SUM(N19:N21) -> 8
B23: Reservas empresariales | D23: HUE-05 (S1) | E23: Crear reserva empresarial | I23: X | J23: 1 | K23: 1 | L23: 1 | M23: 1 | N23: =SUM(J23:M23) -> 4
D24: HUE-05 (S2) | E24: Vista compartida de reserva | I24: X | J24: 1 | K24: 1 | L24: 1 | M24: 0 | N24: =SUM(J24:M24) -> 3
D25: HUE-05 (S3) | E25: Reserva en contexto personal | I25: X | J25: 1 | K25: 1 | L25: 0 | M25: 1 | N25: =SUM(J25:M25) -> 3
D26: HUE-06 (S1) | E26: Miembro sin botón de eliminar | G26: X | I26: X | J26: 1 | K26: 1 | L26: 1 | M26: 0 | N26: =SUM(J26:M26) -> 3
D27: HUE-06 (S2) | E27: Admin elimina reserva | I27: X | J27: 1 | K27: 1 | L27: 1 | M27: 1 | N27: =SUM(J27:M27) -> 4
D28: HUE-06 (S3) | E28: Miembro intenta eliminar por URL | H28: X | I28: X | J28: 1 | K28: 1 | L28: 1 | M28: 1 | N28: =SUM(J28:M28) -> 4
B29: Total — Reservas empresariales | J29: =SUM(J23:J28) -> 6 | K29: =SUM(K23:K28) -> 6 | L29: =SUM(L23:L28) -> 5 | M29: =SUM(M23:M28) -> 4 | N29: =SUM(N23:N28) -> 21
B30: Total Organización / Compañía | J30: =J14+J18+J22+J29 -> 16 | K30: =K14+K18+K22+K29 -> 18 | L30: =L14+L18+L22+L29 -> 15 | M30: =M14+M18+M22+M29 -> 7 | N30: =N14+N18+N22+N29 -> 56
B32: LEYENDA — Grupos de datos
B33: G1 — Organización | E33: Datos de la empresa: razón comercial, RUC, email, panel administrativo, historial de acciones, estado de activación.
B34: G2 — Miembro / invitación | E34: Miembros de la organización e invitaciones: cliente invitado, email, rol, estado (pendiente/aceptado/rechazado), eliminación de miembro.
B35: G3 — Contexto operativo | E35: Contexto personal vs. organizacional: selector, indicador visual, empresa activa, recarga del panel según contexto.
B36: G4 — Reserva empresarial | E36: Reserva vinculada a la organización (no al cliente individual): fechas, bodega, miembro que la creó, control de eliminación, permisos.
B38: Notación COSMIC: E = Entrada (el sistema recibe datos) · X = Salida (el sistema envía datos) · R = Lectura (el sistema lee datos almacenados) · W = Escritura (el sistema almacena/modifica datos) · 1 movimiento de datos = 1 CFP

Sheet Leodeguita
B2: Leodeguita — Mobile (HUL)
B4: Componentes | D4: Historia | E4: Procesos Funcionales | F4: Grupos de datos | J4: Metodología COSMIC
F6: G1 Usuario / autenticación | G6: G2 Empresa / contexto | H6: G3 Bodega (publicación) | I6: G4 Bodega (exploración) | J6: E | K6: X | L6: R | M6: W | N6: CFP
B8: Autenticación | D8: HUL-01 (S1) | E8: Login exitoso | F8: X | J8: 1 | K8: 1 | L8: 1 | M8: 0 | N8: =SUM(J8:M8) -> 3
D9: HUL-01 (S2) | E9: Credenciales incorrectas | F9: X | J9: 1 | K9: 1 | L9: 1 | M9: 0 | N9: =SUM(J9:M9) -> 3
D10: HUL-01 (S3) | E10: Campos vacíos | F10: X | J10: 1 | K10: 1 | L10: 0 | M10: 0 | N10: =SUM(J10:M10) -> 2
B11: Total — Autenticación | J11: =SUM(J8:J10) -> 3 | K11: =SUM(K8:K10) -> 3 | L11: =SUM(L8:L10) -> 2 | M11: =SUM(M8:M10) -> 0 | N11: =SUM(N8:N10) -> 8
B12: Selección de empresa | D12: HUL-02 (S1) | E12: Cliente con múltiples empresas | G12: X | J12: 1 | K12: 1 | L12: 1 | M12: 0 | N12: =SUM(J12:M12) -> 3
D13: HUL-02 (S2) | E13: Cliente con una empresa | G13: X | J13: 1 | K13: 1 | L13: 1 | M13: 0 | N13: =SUM(J13:M13) -> 3
D14: HUL-02 (S3) | E14: Cliente sin empresas | G14: X | J14: 1 | K14: 1 | L14: 1 | M14: 0 | N14: =SUM(J14:M14) -> 3
B15: Total — Selección de empresa | J15: =SUM(J12:J14) -> 3 | K15: =SUM(K12:K14) -> 3 | L15: =SUM(L12:L14) -> 3 | M15: =SUM(M12:M14) -> 0 | N15: =SUM(N12:N14) -> 9
B16: Publicación de bodegas móvil | D16: HUL-03 (S1) | E16: Publicar bodega móvil | H16: X | J16: 1 | K16: 1 | L16: 0 | M16: 1 | N16: =SUM(J16:M16) -> 3
D17: HUL-03 (S2) | E17: Publicar con campos incompletos | H17: X | J17: 1 | K17: 1 | L17: 0 | M17: 0 | N17: =SUM(J17:M17) -> 2
D18: HUL-03 (S3) | E18: Nombre duplicado | H18: X | J18: 1 | K18: 1 | L18: 1 | M18: 0 | N18: =SUM(J18:M18) -> 3
D19: HUL-04 (S1) | E19: Ver bodegas publicadas | H19: X | J19: 0 | K19: 1 | L19: 1 | M19: 0 | N19: =SUM(J19:M19) -> 2
D20: HUL-04 (S2) | E20: Sin bodegas publicadas | H20: X | J20: 0 | K20: 1 | L20: 1 | M20: 0 | N20: =SUM(J20:M20) -> 2
D21: HUL-04 (S3) | E21: Filtrar bodegas | H21: X | J21: 1 | K21: 1 | L21: 1 | M21: 0 | N21: =SUM(J21:M21) -> 3
B22: Total — Publicación de bodegas móvil | J22: =SUM(J16:J21) -> 4 | K22: =SUM(K16:K21) -> 6 | L22: =SUM(L16:L21) -> 4 | M22: =SUM(M16:M21) -> 1 | N22: =SUM(N16:N21) -> 15
B23: Exploración de espacios móvil | D23: HUL-05 (S1) | E23: Ver espacios disponibles | I23: X | J23: 0 | K23: 1 | L23: 1 | M23: 0 | N23: =SUM(J23:M23) -> 2
D24: HUL-05 (S2) | E24: Sin espacios disponibles | I24: X | J24: 0 | K24: 1 | L24: 1 | M24: 0 | N24: =SUM(J24:M24) -> 2
D25: HUL-05 (S3) | E25: Filtrar espacios | I25: X | J25: 1 | K25: 1 | L25: 1 | M25: 0 | N25: =SUM(J25:M25) -> 3
D26: HUL-06 (S1) | E26: Ver detalle de bodega móvil | I26: X | J26: 1 | K26: 1 | L26: 1 | M26: 0 | N26: =SUM(J26:M26) -> 3
D27: HUL-06 (S2) | E27: Detalle con información parcial | I27: X | J27: 1 | K27: 1 | L27: 1 | M27: 0 | N27: =SUM(J27:M27) -> 3
D28: HUL-06 (S3) | E28: Bodega ya no disponible | I28: X | J28: 1 | K28: 1 | L28: 1 | M28: 0 | N28: =SUM(J28:M28) -> 3
B29: Total — Exploración de espacios móvil | J29: =SUM(J23:J28) -> 4 | K29: =SUM(K23:K28) -> 6 | L29: =SUM(L23:L28) -> 6 | M29: =SUM(M23:M28) -> 0 | N29: =SUM(N23:N28) -> 16
B30: Total Leodeguita — Mobile | J30: =J11+J15+J22+J29 -> 14 | K30: =K11+K15+K22+K29 -> 18 | L30: =L11+L15+L22+L29 -> 15 | M30: =M11+M15+M22+M29 -> 1 | N30: =N11+N15+N22+N29 -> 48
B32: LEYENDA — Grupos de datos
B33: G1 — Usuario / autenticación | E33: Credenciales Leodega: email, contraseña, cuenta de usuario, rol, redirección tras login.
B34: G2 — Empresa / contexto | E34: Selección de empresa en la app móvil: empresas asociadas al cliente, empresa activa, selector, vista filtrada.
B35: G3 — Bodega (publicación) | E35: Registro y listado de bodegas desde móvil: datos del formulario, estado (pendiente/aprobada), nombre duplicado, filtros.
B36: G4 — Bodega (exploración) | E36: Exploración de espacios disponibles: lista unificada, filtros, detalle de bodega, capacidad, ubicación, manager responsable.
B38: Notación COSMIC: E = Entrada (el sistema recibe datos) · X = Salida (el sistema envía datos) · R = Lectura (el sistema lee datos almacenados) · W = Escritura (el sistema almacena/modifica datos) · 1 movimiento de datos = 1 CFP
